<?xml version="1.0"?>
<robot xmlns:xacro="http://www.ros.org/wiki/xacro">
	<link name="base_link">
	</link>
	<joint name="chassis_joint" type="fixed">
	    <parent link="base_link"/>
	    <child link="chassis"/>
	    <origin xyz="0.0 0.0 0"/>
	</joint>

	<link name="chassis">
	    <visual>
	        <origin xyz="0.0 0.0 0.03" rpy="0 0 0"/>
	        <geometry>
	            <box size="0.19 0.15 0.06"/>
	        </geometry>
	        <material name="white"/>
	    </visual>
	</link>

<!-- LEFT F WHEEL -->
<joint name="left_f_wheel_joint" type="continuous">
    <parent link="chassis"/>
    <child link="left_f_wheel"/>
    <origin xyz="-0.07 0.092 0.015" rpy="-${pi/2} 0 0"/>
  
    <axis xyz="0 0 1"/>
</joint>

<link name="left_f_wheel">
    <visual>
        <geometry>
            <cylinder length="0.025" radius="0.025" />
        </geometry>
        <material name="blue"/>
    </visual>
</link>

<!-- LEFT B WHEEL -->
<joint name="left_b_wheel_joint" type="continuous">
    <parent link="chassis"/>
    <child link="left_b_wheel"/>
    <origin xyz="0.07 0.092 0.015" rpy="-${pi/2} 0 0"/>
    <axis xyz="0 0 1"/>
</joint>

<link name="left_b_wheel">
    <visual>
        <geometry>
            <cylinder length="0.025" radius="0.025" />
        </geometry>
        <material name="blue"/>
    </visual>
</link>

<!-- RIGHT F WHEEL -->
<joint name="right_f_wheel_joint" type="continuous">
    <parent link="chassis"/>
    <child link="right_f_wheel"/>
    <origin xyz="-0.07 -0.092 0.015" rpy="-${pi/2} 0 0"/>
  
    <axis xyz="0 0 1"/>
</joint>

<link name="right_f_wheel">
    <visual>
        <geometry>
            <cylinder length="0.025" radius="0.025" />
        </geometry>
        <material name="blue"/>
    </visual>
</link>

<!-- RIGHT B WHEEL -->
<joint name="right_b_wheel_joint" type="continuous">
    <parent link="chassis"/>
    <child link="right_b_wheel"/>
    <origin xyz="0.07 -0.092 0.015" rpy="-${pi/2} 0 0"/>
    <axis xyz="0 0 1"/>
</joint>

<link name="right_b_wheel">
    <visual>
        <geometry>
            <cylinder length="0.025" radius="0.025" />
        </geometry>
        <material name="blue"/>
    </visual>
</link>

</robot>
